Workbook

Sheet Data Keys
A1: Name | B1: Code | C1: User | D1: Serial Number | E1: Location | H1: Name | I1: User | J1: Code | K1: Serial Number | L1: Location | Q1: ADDITIONAL KEYS GIVEN | T1: MC | U1: Laundry Tag
A2: 27/1/E1/1 | B2: 6483CE93 | C2: sadmin | D2: key | E2: Accommodation Keys | H2: 452127 | I2: 452127 Sebastian | J2: Bag 0189 | K2: 189 | L2: Laundry Bags in Use
A3: 27/1/E1/2 | B3: D4F4CC93 | C3: sadmin | D3: key | E3: Accommodation Keys | H3: Bag 0824 | I3: sadmin | J3: Bag 0824 | K3: 824 | L3: Unreceived Bags
A4: 27/1/E1/3 | B4: B40DED93 | C4: sadmin | D4: key | E4: Accommodation Keys | H4: 506372 | I4: 506372 Magnus | J4: Bag 0447 | K4: 447 | L4: Laundry Bags in Use
A5: 27/1/E2/1 | B5: 14E0DB93 | C5: sadmin | D5: key | E5: Accommodation Keys | H5: 472536 | I5: 472536 Alexander | J5: Bag 0455 | K5: 455 | L5: Laundry Bags in Use
A6: 27/1/E2/2 | B6: 2413CD93 | C6: sadmin | D6: key | E6: Accommodation Keys | H6: 508884 | I6: 508884 Jes | J6: Bag 0232 | K6: 232 | L6: Laundry Bags in Use
A7: 27/1/E2/3 | B7: 74D8DF93 | C7: sadmin | D7: key | E7: Accommodation Keys | H7: 410103 | I7: 410103 Kasper | J7: Bag 0615 | K7: 615 | L7: Laundry Bags in Use
A8: 27/101/1 | B8: C487F493 | C8: 99901 Richard | D8: key | E8: Accommodation Keys | H8: 393712 | I8: 393712 Peter | J8: Bag 0620 | K8: 620 | L8: Laundry Bags in Use | M8: C487F493 | Q8: 32/205/1 | R8: D47FDD93 | S8: 167039 Jesper | T8: 0368 | U8: 893
A9: 27/101/2 | B9: 743DE893 | D9: key | E9: Accommodation Keys | H9: 534522 | I9: 534522 Michael | J9: Bag 0641 | K9: 641 | L9: Laundry Bags in Use | S9: 399105 Chris
A10: 27/101/3 | B10: A473CD93 | D10: key | E10: Accommodation Keys | H10: Bag 0305 | I10: sadmin | J10: Bag 0305 | K10: 305 | L10: Laundry Bags Depot | S10: 443003 Jesper
A11: 27/102/1 | B11: A435E293 | C11: 99903 Hakan | D11: key | E11: Accommodation Keys | H11: 439367 | I11: 439367 Malthe | J11: Bag 0724 | K11: 724 | L11: Laundry Bags in Use | M11: A435E293 | Q11: 32/206/1 | R11: B4E2D093 | S11: 399105 Chris
A12: 27/102/2 | B12: C487F493 | D12: key | E12: Accommodation Keys | H12: 478336 | I12: 478336 Johannes | J12: Bag 0059 | K12: 59 | L12: Laundry Bags in Use | S12: 399105 Chris
A13: 27/102/3 | B13: 64E1D593 | D13: key | E13: Accommodation Keys | H13: Bag 0394 | I13: sadmin | J13: Bag 0394 | K13: 394 | L13: Laundry Bags Depot | S13: 443003 Jesper
A14: 27/103/1 | B14: E4464694 | C14: 99905 Torbjorn | D14: key | E14: Accommodation Keys | H14: 307201 | I14: 307201 Yoan | J14: Bag 0909 | K14: 909 | L14: Laundry Bags in Use | M14: E4464694 | Q14: 32/207/1 | R14: 64D0D393 | S14: 443003 Jesper
A15: 27/103/2 | B15: 3416CF93 | D15: key | E15: Accommodation Keys | H15: Bag 0838 | I15: sadmin | J15: Bag 0838 | K15: 838 | L15: Unreceived Bags | S15: 399105 Chris
A16: 27/103/3 | B16: C456E093 | D16: key | E16: Accommodation Keys | H16: 193022 | I16: 193022 Claus | J16: Bag 0974 | K16: 974 | L16: Laundry Bags in Use | S16: 443003 Jesper
A17: 27/104/1 | B17: 44A5E293 | C17: 99907 Kateryna | D17: key | E17: Accommodation Keys | H17: 194935 | I17: 194935 Karsten | J17: Bag 0047 | K17: 47 | L17: Laundry Bags in Use | M17: 44A5E293 | Q17: 32/215/1 | R17: 1455E193 | S17: 500640 Philip
A18: 27/104/2 | B18: B4B14194 | D18: key | E18: Accommodation Keys | H18: 397279 | I18: 397279 Jesper | J18: Bag 0545 | K18: 545 | L18: Laundry Bags in Use
A19: 27/104/3 | B19: 140DF093 | D19: key | E19: Accommodation Keys | H19: Bag 0847 | I19: sadmin | J19: Bag 0847 | K19: 847 | L19: Unreceived Bags
A20: 27/105/1 | B20: A427D093 | C20: 99909 Bjorn | D20: key | E20: Accommodation Keys | H20: 511788 | I20: 511788 Ghislain | J20: Bag 1011 | K20: 1011 | L20: Laundry Bags in Use | M20: A427D093 | Q20: 32/208/1 | R20: E4454794 | S20: 514113 Abdul
A21: 27/105/2 | B21: A427D093 | D21: key | E21: Accommodation Keys | H21: Bag 0848 | I21: sadmin | J21: Bag 0848 | K21: 848 | L21: Unreceived Bags
A22: 27/105/3 | B22: 248DE193 | D22: key | E22: Accommodation Keys | H22: 431628 | I22: 431628 Marc | J22: Bag 1000 | K22: 1000 | L22: Laundry Bags in Use
A23: 27/106/1 | B23: 842FE293 | C23: 99911 Bjorn | D23: key | E23: Accommodation Keys | H23: 494353 | I23: 494353 Mikkel | J23: Bag 0768 | K23: 768 | L23: Laundry Bags in Use | M23: 842FE293
A24: 27/106/2 | B24: 84B5D293 | D24: key | E24: Accommodation Keys | H24: 495997 | I24: 495997 Sandra | J24: Bag 1104 | K24: 1104 | L24: Laundry Bags in Use
A25: 27/106/3 | B25: A4F5DC93 | D25: key | E25: Accommodation Keys | H25: 495475 | I25: 495475 Stefan | J25: Bag 1024 | K25: 1024 | L25: Laundry Bags in Use
A26: 27/107/1 | B26: 747ECC93 | C26: 99913 Ida | D26: key | E26: Accommodation Keys | H26: 456552 | I26: 456552 Oliver | J26: Bag 0513 | K26: 513 | L26: Laundry Bags in Use | M26: 747ECC93
A27: 27/107/2 | B27: 44C74594 | D27: key | E27: Accommodation Keys | H27: 303575 | I27: 303575 Rasmus | J27: Bag 0243 | K27: 243 | L27: Laundry Bags in Use
A28: 27/107/3 | B28: 746FE193 | D28: key | E28: Accommodation Keys | H28: 197679 | I28: 197679 Niels Erik | J28: Bag 0674 | K28: 674 | L28: Laundry Bags in Use
A29: 27/108/1 | B29: 944FE193 | C29: 99914 Maria | D29: key | E29: Accommodation Keys | H29: 171119 | I29: 171119 Olivier | J29: Bag 0820 | K29: 820 | L29: Laundry Bags in Use | M29: 944FE193
A30: 27/108/2 | B30: 34DCEE93 | D30: key | E30: Accommodation Keys | H30: 485435 | I30: 485435 Micki | J30: Bag 0654 | K30: 654 | L30: Laundry Bags in Use
A31: 27/108/3 | B31: 04EED593 | D31: key | E31: Accommodation Keys | H31: 456401 | I31: 456401 Patrick | J31: Bag 0740 | K31: 740 | L31: Laundry Bags in Use
A32: 27/109/1 | B32: E46BD893 | C32: 99915 Rickard | D32: key | E32: Accommodation Keys | H32: Bag 0822 | I32: sadmin | J32: Bag 0822 | K32: 822 | L32: Unreceived Bags | M32: E46BD893
A33: 27/109/2 | B33: 04D23B94 | D33: key | E33: Accommodation Keys | H33: 459106 | I33: 459106 Daniel | J33: Bag 0015 | K33: 15 | L33: Laundry Bags in Use
A34: 27/109/3 | B34: 3484F493 | D34: key | E34: Accommodation Keys | H34: 509424 | I34: 509424 Emil | J34: Bag 0084 | K34: 84 | L34: Laundry Bags in Use
A35: 27/110/1 | B35: 6454CB93 | C35: 99917 Patrik | D35: key | E35: Accommodation Keys | H35: Bag 0454 | I35: sadmin | J35: Bag 0454 | K35: 454 | L35: Unreceived Bags | M35: 6454CB93
A36: 27/110/2 | B36: D4BD3794 | D36: key | E36: Accommodation Keys | H36: Bag 0357 | I36: sadmin | J36: Bag 0357 | K36: 357 | L36: Laundry Bags Depot
A37: 27/110/3 | B37: 94D2E493 | D37: key | E37: Accommodation Keys | H37: Bag 0381 | I37: sadmin | J37: Bag 0381 | K37: 381 | L37: Laundry Bags Depot
A38: 27/111/1 | B38: D4763894 | C38: 99919 Jimmy | D38: key | E38: Accommodation Keys | H38: Bag 0063 | I38: sadmin | J38: Bag 0063 | K38: 63 | L38: Laundry Bags Depot | M38: D4763894
A39: 27/111/2 | B39: E42AE193 | D39: key | E39: Accommodation Keys | H39: 425459 | I39: 425459 Mads | J39: Bag 0885 | K39: 885 | L39: Laundry Bags in Use
A40: 27/111/3 | B40: 6449F493 | D40: key | E40: Accommodation Keys | H40: 501115 | I40: 501115 Villads | J40: Bag 0696 | K40: 696 | L40: Laundry Bags in Use
...

Sheet All
B2: # | C2: NAME, ID | D2: Nation | E2: Buil ding | F2: ROOM | L2: Placed Beds | P2: Date | T2: Remarks | Y2: Planed accomodation
F3: Used | G3: Single | H3: Double | I3: Triple | J3: Quadre | K3: Empty | L3: 1 | M3: 2 | N3: 3 | O3: 4 | P3: ETA | Q3: ETD | R3: MC | S3: L. Bag | Y3: Accomodated
C4: =G4+H4*2+I4*3 -> 105 | F4: =SUM(G4:I4) -> 52 | G4: =COUNTIFS(G6:K1251,"=Single") -> 9 | H4: =COUNTIFS(G6:K1251,"=Double") -> 33 | I4: =COUNTIFS(G6:K1251,"=Triple") -> 10 | J4: =COUNTIFS(G6:K1251,"=Quadre") -> 25 | K4: =COUNTIFS(G6:K1251,"=Empty") -> 1 | L4: =COUNTIFS(M6:O1251,"=1") -> 9 | M4: =COUNTIFS(M6:O1251,"=2") -> 33 | N4: =COUNTIFS(M6:O1251,"=3") -> 10 | O4: =COUNTIFS(M6:O1251,"=4") -> 27 | R4: ='27'!Z4+#REF!+#REF!+#REF!+#REF!+'32'!AB4+#REF!+#REF!+#REF!+#REF! -> #REF! | S4: ='27'!AA4+#REF!+#REF!+#REF!+#REF!+'32'!AC4+#REF!+#REF!+#REF!+#REF! -> #REF! | Y4: Leaved
L5: =SUM(M6:O1265) -> #REF! | M5: beds/rooms | O5: =L4+M4+N4+O4 -> 79 | Y5: Non correct date
B6: =COUNTA(C6)-IF(C6=0,1) -> 1 | C6: ='27'!M6 -> 99901 Richard | D6: =IF('27'!N6=0,"",'27'!N6) | E6: ='27'!O6 -> 27 | F6: ='27'!P6 -> 101 | G6: ='27'!Q6 -> Double | L6: ='27'!U6 -> 0 | M6: ='27'!V6 -> 2 | O6: ='27'!W6 -> 0 | P6: =IF('27'!X6=0,"",'27'!X6) | Q6: =IF('27'!Y6=0,"",'27'!Y6) | R6: =IF('27'!Z6=0,"",'27'!Z6) | S6: =IF('27'!AA6=0,"",'27'!AA6) -> #N/A | T6: Changed on 18.08
B7: =COUNTA(C7)-IF(C7=0,1)+B6 -> 1 | C7: ='27'!M7 -> 0 | D7: =IF('27'!N7=0,"",'27'!N7) -> DNK | E7: ='27'!O7 -> 27 | F7: ='27'!P7 -> 101 | L7: ='27'!U7 -> 2 | M7: ='27'!V7 -> 0 | O7: ='27'!W7 -> 0 | P7: =IF('27'!X7=0,"",'27'!X7) | Q7: =IF('27'!Y7=0,"",'27'!Y7) | R7: =IF('27'!Z7=0,"",'27'!Z7) -> 0002 | S7: =IF('27'!AA7=0,"",'27'!AA7) -> #N/A
B8: =COUNTA(C8)-IF(C8=0,1)+B7 -> 1 | C8: ='27'!M8 -> 0 | D8: =IF('27'!N8=0,"",'27'!N8) -> DNK | E8: ='27'!O8 -> 27 | F8: ='27'!P8 -> 101 | L8: ='27'!U8 -> 3 | M8: ='27'!V8 -> 0 | O8: ='27'!W8 -> 0 | P8: =IF('27'!X8=0,"",'27'!X8) | Q8: =IF('27'!Y8=0,"",'27'!Y8) | R8: =IF('27'!Z8=0,"",'27'!Z8) | S8: =IF('27'!AA8=0,"",'27'!AA8) -> #N/A | T8: Changed on 18.08
B9: =COUNTA(C9)-IF(C9=0,1)+B8 -> 2 | C9: ='27'!M9 -> 99903 Hakan | D9: =IF('27'!N9=0,"",'27'!N9) -> DNK | E9: ='27'!O9 -> 27 | F9: ='27'!P9 -> 102 | G9: ='27'!Q9 -> Double | L9: ='27'!U9 -> 1 | M9: ='27'!V9 -> 2 | O9: ='27'!W9 -> 0 | P9: =IF('27'!X9=0,"",'27'!X9) | Q9: =IF('27'!Y9=0,"",'27'!Y9) | R9: =IF('27'!Z9=0,"",'27'!Z9) -> 0004 | S9: =IF('27'!AA9=0,"",'27'!AA9) -> #N/A
B10: =COUNTA(C10)-IF(C10=0,1)+B9 -> 2 | C10: ='27'!M10 -> 0 | D10: =IF('27'!N10=0,"",'27'!N10) | E10: ='27'!O10 -> 27 | F10: ='27'!P10 -> 102 | L10: ='27'!U10 -> 0 | M10: ='27'!V10 -> 0 | O10: ='27'!W10 -> 0 | P10: =IF('27'!X10=0,"",'27'!X10) | Q10: =IF('27'!Y10=0,"",'27'!Y10) | R10: =IF('27'!Z10=0,"",'27'!Z10) | S10: =IF('27'!AA10=0,"",'27'!AA10) -> #N/A
B11: =COUNTA(C11)-IF(C11=0,1)+B10 -> 2 | C11: ='27'!M11 -> 0 | D11: =IF('27'!N11=0,"",'27'!N11) -> DNK | E11: ='27'!O11 -> 27 | F11: ='27'!P11 -> 102 | L11: ='27'!U11 -> 3 | M11: ='27'!V11 -> 0 | O11: ='27'!W11 -> 0 | P11: =IF('27'!X11=0,"",'27'!X11) | Q11: =IF('27'!Y11=0,"",'27'!Y11) | R11: =IF('27'!Z11=0,"",'27'!Z11) -> 0005 | S11: =IF('27'!AA11=0,"",'27'!AA11) -> #N/A
B12: =COUNTA(C12)-IF(C12=0,1)+B11 -> 3 | C12: ='27'!M12 -> 99905 Torbjorn | D12: =IF('27'!N12=0,"",'27'!N12) -> DNK | E12: ='27'!O12 -> 27 | F12: ='27'!P12 -> 103 | G12: ='27'!Q12 -> Double | H12: ='27'!R12 -> 0 | I12: ='27'!S12 -> 0 | K12: ='27'!T12 -> 0 | L12: ='27'!U12 -> 1 | M12: ='27'!V12 -> 2 | O12: ='27'!W12 -> 0 | P12: =IF('27'!X12=0,"",'27'!X12) | Q12: =IF('27'!Y12=0,"",'27'!Y12) | R12: =IF('27'!Z12=0,"",'27'!Z12) -> 0006 | S12: =IF('27'!AA12=0,"",'27'!AA12) -> Bag 0167
B13: =COUNTA(C13)-IF(C13=0,1)+B12 -> 3 | C13: ='27'!M13 -> 0 | D13: =IF('27'!N13=0,"",'27'!N13) | E13: ='27'!O13 -> 27 | F13: ='27'!P13 -> 103 | G13: ='27'!Q13 -> 0 | H13: ='27'!R13 -> 0 | I13: ='27'!S13 -> 0 | K13: ='27'!T13 -> 0 | L13: ='27'!U13 -> 0 | M13: ='27'!V13 -> 0 | O13: ='27'!W13 -> 0 | P13: =IF('27'!X13=0,"",'27'!X13) | Q13: =IF('27'!Y13=0,"",'27'!Y13) | R13: =IF('27'!Z13=0,"",'27'!Z13) | S13: =IF('27'!AA13=0,"",'27'!AA13) -> #N/A
B14: =COUNTA(C14)-IF(C14=0,1)+B13 -> 3 | C14: ='27'!M14 -> 0 | D14: =IF('27'!N14=0,"",'27'!N14) -> DNK | E14: ='27'!O14 -> 27 | F14: ='27'!P14 -> 103 | G14: ='27'!Q14 -> 0 | H14: ='27'!R14 -> 0 | I14: ='27'!S14 -> 0 | K14: ='27'!T14 -> 0 | L14: ='27'!U14 -> 3 | M14: ='27'!V14 -> 0 | O14: ='27'!W14 -> 0 | P14: =IF('27'!X14=0,"",'27'!X14) | Q14: =IF('27'!Y14=0,"",'27'!Y14) | R14: =IF('27'!Z14=0,"",'27'!Z14) -> 0007 | S14: =IF('27'!AA14=0,"",'27'!AA14) -> #N/A
B15: =COUNTA(C15)-IF(C15=0,1)+B14 -> 4 | C15: ='27'!M15 -> 99907 Kateryna | D15: =IF('27'!N15=0,"",'27'!N15) -> DNK | E15: ='27'!O15 -> 27 | F15: ='27'!P15 -> 104 | G15: ='27'!Q15 -> Triple | H15: ='27'!R15 -> 0 | I15: ='27'!S15 -> 0 | K15: ='27'!T15 -> 0 | L15: ='27'!U15 -> 1 | M15: ='27'!V15 -> 3 | O15: ='27'!W15 -> 0 | P15: =IF('27'!X15=0,"",'27'!X15) | Q15: =IF('27'!Y15=0,"",'27'!Y15) | R15: =IF('27'!Z15=0,"",'27'!Z15) -> 0008 | S15: =IF('27'!AA15=0,"",'27'!AA15) -> #N/A
B16: =COUNTA(C16)-IF(C16=0,1)+B15 -> 4 | C16: ='27'!M16 -> 0 | D16: =IF('27'!N16=0,"",'27'!N16) -> DNK | E16: ='27'!O16 -> 27 | F16: ='27'!P16 -> 104 | G16: ='27'!Q16 -> 0 | H16: ='27'!R16 -> 0 | I16: ='27'!S16 -> 0 | K16: ='27'!T16 -> 0 | L16: ='27'!U16 -> 2 | M16: ='27'!V16 -> 0 | O16: ='27'!W16 -> 0 | P16: =IF('27'!X16=0,"",'27'!X16) | Q16: =IF('27'!Y16=0,"",'27'!Y16) | R16: =IF('27'!Z16=0,"",'27'!Z16) -> 0010 | S16: =IF('27'!AA16=0,"",'27'!AA16) -> #N/A
B17: =COUNTA(C17)-IF(C17=0,1)+B16 -> 4 | C17: ='27'!M17 -> 0 | D17: =IF('27'!N17=0,"",'27'!N17) -> DNK | E17: ='27'!O17 -> 27 | F17: ='27'!P17 -> 104 | G17: ='27'!Q17 -> 0 | H17: ='27'!R17 -> 0 | I17: ='27'!S17 -> 0 | K17: ='27'!T17 -> 0 | L17: ='27'!U17 -> 3 | M17: ='27'!V17 -> 0 | O17: ='27'!W17 -> 0 | P17: =IF('27'!X17=0,"",'27'!X17) | Q17: =IF('27'!Y17=0,"",'27'!Y17) | R17: =IF('27'!Z17=0,"",'27'!Z17) -> 0009 | S17: =IF('27'!AA17=0,"",'27'!AA17) -> #N/A
B18: =COUNTA(C18)-IF(C18=0,1)+B17 -> 5 | C18: ='27'!M18 -> 99909 Bjorn | D18: =IF('27'!N18=0,"",'27'!N18) -> DNK | E18: ='27'!O18 -> 27 | F18: ='27'!P18 -> 105 | G18: ='27'!Q18 -> Double | H18: ='27'!R18 -> 0 | I18: ='27'!S18 -> 0 | K18: ='27'!T18 -> 0 | L18: ='27'!U18 -> 1 | M18: ='27'!V18 -> 2 | O18: ='27'!W18 -> 0 | P18: =IF('27'!X18=0,"",'27'!X18) | Q18: =IF('27'!Y18=0,"",'27'!Y18) | R18: =IF('27'!Z18=0,"",'27'!Z18) -> 0011 | S18: =IF('27'!AA18=0,"",'27'!AA18) -> #N/A
B19: =COUNTA(C19)-IF(C19=0,1)+B18 -> 5 | C19: ='27'!M19 -> 0 | D19: =IF('27'!N19=0,"",'27'!N19) | E19: ='27'!O19 -> 27 | F19: ='27'!P19 -> 105 | G19: ='27'!Q19 -> 0 | H19: ='27'!R19 -> 0 | I19: ='27'!S19 -> 0 | K19: ='27'!T19 -> 0 | L19: ='27'!U19 -> 0 | M19: ='27'!V19 -> 0 | O19: ='27'!W19 -> 0 | P19: =IF('27'!X19=0,"",'27'!X19) | Q19: =IF('27'!Y19=0,"",'27'!Y19) | R19: =IF('27'!Z19=0,"",'27'!Z19) | S19: =IF('27'!AA19=0,"",'27'!AA19) -> #N/A
B20: =COUNTA(C20)-IF(C20=0,1)+B19 -> 5 | C20: ='27'!M20 -> 0 | D20: =IF('27'!N20=0,"",'27'!N20) -> DNK | E20: ='27'!O20 -> 27 | F20: ='27'!P20 -> 105 | G20: ='27'!Q20 -> 0 | H20: ='27'!R20 -> 0 | I20: ='27'!S20 -> 0 | K20: ='27'!T20 -> 0 | L20: ='27'!U20 -> 3 | M20: ='27'!V20 -> 0 | O20: ='27'!W20 -> 0 | P20: =IF('27'!X20=0,"",'27'!X20) | Q20: =IF('27'!Y20=0,"",'27'!Y20) | R20: =IF('27'!Z20=0,"",'27'!Z20) -> 0012 | S20: =IF('27'!AA20=0,"",'27'!AA20) -> #N/A
B21: =COUNTA(C21)-IF(C21=0,1)+B20 -> 6 | C21: ='27'!M21 -> 99911 Bjorn | D21: =IF('27'!N21=0,"",'27'!N21) | E21: ='27'!O21 -> 27 | F21: ='27'!P21 -> 106 | G21: ='27'!Q21 -> Double | H21: ='27'!R21 -> 0 | I21: ='27'!S21 -> 0 | K21: ='27'!T21 -> 0 | L21: ='27'!U21 -> 0 | M21: ='27'!V21 -> 2 | O21: ='27'!W21 -> 0 | P21: =IF('27'!X21=0,"",'27'!X21) | Q21: =IF('27'!Y21=0,"",'27'!Y21) | R21: =IF('27'!Z21=0,"",'27'!Z21) | S21: =IF('27'!AA21=0,"",'27'!AA21) -> #N/A
B22: =COUNTA(C22)-IF(C22=0,1)+B21 -> 6 | C22: ='27'!M22 -> 0 | D22: =IF('27'!N22=0,"",'27'!N22) -> DNK | E22: ='27'!O22 -> 27 | F22: ='27'!P22 -> 106 | G22: ='27'!Q22 -> 0 | H22: ='27'!R22 -> 0 | I22: ='27'!S22 -> 0 | K22: ='27'!T22 -> 0 | L22: ='27'!U22 -> 2 | M22: ='27'!V22 -> 0 | O22: ='27'!W22 -> 0 | P22: =IF('27'!X22=0,"",'27'!X22) | Q22: =IF('27'!Y22=0,"",'27'!Y22) | R22: =IF('27'!Z22=0,"",'27'!Z22) -> 0013 | S22: =IF('27'!AA22=0,"",'27'!AA22) -> #N/A
B23: =COUNTA(C23)-IF(C23=0,1)+B22 -> 6 | C23: ='27'!M23 -> 0 | D23: =IF('27'!N23=0,"",'27'!N23) -> DNK | E23: ='27'!O23 -> 27 | F23: ='27'!P23 -> 106 | G23: ='27'!Q23 -> 0 | H23: ='27'!R23 -> 0 | I23: ='27'!S23 -> 0 | K23: ='27'!T23 -> 0 | L23: ='27'!U23 -> 3 | M23: ='27'!V23 -> 0 | O23: ='27'!W23 -> 0 | P23: =IF('27'!X23=0,"",'27'!X23) | Q23: =IF('27'!Y23=0,"",'27'!Y23) | R23: =IF('27'!Z23=0,"",'27'!Z23) -> 0014 | S23: =IF('27'!AA23=0,"",'27'!AA23) -> #N/A
... B83: =COUNTA(C83)-IF(C83=0,1)+B82 -> 29 | C83: ='27'!M83 -> 0 | D83: =IF('27'!N83=0,"",'27'!N83) -> DNK | E83: ='27'!O83 -> 27 | F83: ='27'!P83 -> 206 | G83: ='27'!Q83 -> 0 | H83: ='27'!R83 -> 0 | I83: ='27'!S83 -> 0 | K83: ='27'!T83 -> 0 | L83: ='27'!U83 -> 3 | M83: ='27'!V83 -> 0 | O83: ='27'!W83 -> 0 | P83: =IF('27'!X83=0,"",'27'!X83) | Q83: =IF('27'!Y83=0,"",'27'!Y83) | R83: =IF('27'!Z83=0,"",'27'!Z83) -> 0056 | S83: =IF('27'!AA83=0,"",'27'!AA83) -> #N/A
B84: =COUNTA(C84)-IF(C84=0,1)+B83 -> 30 | C84: ='27'!M84 -> 99951 Anton.W 13/1-20/1 Guest | D84: =IF('27'!N84=0,"",'27'!N84) | E84: ='27'!O84 -> 27 | F84: ='27'!P84 -> 207 | G84: ='27'!Q84 -> Single | H84: ='27'!R84 -> 0 | I84: ='27'!S84 -> 0 | K84: ='27'!T84 -> 0 | L84: ='27'!U84 -> 1 | M84: ='27'!V84 -> 1 | O84: ='27'!W84 -> 0 | P84: =IF('27'!X84=0,"",'27'!X84) | Q84: =IF('27'!Y84=0,"",'27'!Y84) | R84: =IF('27'!Z84=0,"",'27'!Z84) -> 0054 | S84: =IF('27'!AA84=0,"",'27'!AA84) -> #N/A | T84: 229827 Thomas, SIM 1, Checked out on 26.08/ MC0057/Bag0217 in the billeting
B85: =COUNTA(C85)-IF(C85=0,1)+B84 -> 30 | C85: ='27'!M85 -> 0 | D85: =IF('27'!N85=0,"",'27'!N85) | E85: ='27'!O85 -> 27 | F85: ='27'!P85 -> 207 | G85: ='27'!Q85 -> 0 | H85: ='27'!R85 -> 0 | I85: ='27'!S85 -> 0 | K85: ='27'!T85 -> 0 | L85: ='27'!U85 -> 0 | M85: ='27'!V85 -> 0 | O85: ='27'!W85 -> 0 | P85: =IF('27'!X85=0,"",'27'!X85) | Q85: =IF('27'!Y85=0,"",'27'!Y85) | R85: =IF('27'!Z85=0,"",'27'!Z85) | S85: =IF('27'!AA85=0,"",'27'!AA85) -> #N/A
B86: =COUNTA(C86)-IF(C86=0,1)+B85 -> 30 | C86: ='27'!M86 -> 0 | D86: =IF('27'!N86=0,"",'27'!N86) | E86: ='27'!O86 -> 27 | F86: ='27'!P86 -> 207 | G86: ='27'!Q86 -> 0 | H86: ='27'!R86 -> 0 | I86: ='27'!S86 -> 0 | K86: ='27'!T86 -> 0 | L86: ='27'!U86 -> 0 | M86: ='27'!V86 -> 0 | O86: ='27'!W86 -> 0 | P86: =IF('27'!X86=0,"",'27'!X86) | Q86: =IF('27'!Y86=0,"",'27'!Y86) | R86: =IF('27'!Z86=0,"",'27'!Z86) | S86: =IF('27'!AA86=0,"",'27'!AA86) -> #N/A
B87: =COUNTA(C87)-IF(C87=0,1)+B86 -> 31 | C87: ='27'!M87 -> 99952 Isac A 13/1-20/1 Guest | D87: =IF('27'!N87=0,"",'27'!N87) | E87: ='27'!O87 -> 27 | F87: ='27'!P87 -> 208 | G87: ='27'!Q87 -> Double | H87: ='27'!R87 -> 0 | I87: ='27'!S87 -> 0 | K87: ='27'!T87 -> 0 | L87: ='27'!U87 -> 0 | M87: ='27'!V87 -> 2 | O87: ='27'!W87 -> 0 | P87: =IF('27'!X87=0,"",'27'!X87) | Q87: =IF('27'!Y87=0,"",'27'!Y87) | R87: =IF('27'!Z87=0,"",'27'!Z87) | S87: =IF('27'!AA87=0,"",'27'!AA87) -> #N/A
B88: =COUNTA(C88)-IF(C88=0,1)+B87 -> 32 | C88: ='27'!M88 -> 99953 Liam B 13/1-20/1 Guest | D88: =IF('27'!N88=0,"",'27'!N88) -> DNK | E88: ='27'!O88 -> 27 | F88: ='27'!P88 -> 208 | G88: ='27'!Q88 -> 0 | H88: ='27'!R88 -> 0 | I88: ='27'!S88 -> 0 | K88: ='27'!T88 -> 0 | L88: ='27'!U88 -> 2 | M88: ='27'!V88 -> 0 | O88: ='27'!W88 -> 0 | P88: =IF('27'!X88=0,"",'27'!X88) | Q88: =IF('27'!Y88=0,"",'27'!Y88) | R88: =IF('27'!Z88=0,"",'27'!Z88) -> 0059 | S88: =IF('27'!AA88=0,"",'27'!AA88) -> #N/A
B89: =COUNTA(C89)-IF(C89=0,1)+B88 -> 32 | C89: ='27'!M89 -> 0 | D89: =IF('27'!N89=0,"",'27'!N89) -> DNK | E89: ='27'!O89 -> 27 | F89: ='27'!P89 -> 208 | G89: ='27'!Q89 -> 0 | H89: ='27'!R89 -> 0 | I89: ='27'!S89 -> 0 | K89: ='27'!T89 -> 0 | L89: ='27'!U89 -> 3 | M89: ='27'!V89 -> 0 | O89: ='27'!W89 -> 0 | P89: =IF('27'!X89=0,"",'27'!X89) | Q89: =IF('27'!Y89=0,"",'27'!Y89) | R89: =IF('27'!Z89=0,"",'27'!Z89) -> 0058 | S89: =IF('27'!AA89=0,"",'27'!AA89) -> #N/A
B90: =COUNTA(C90)-IF(C90=0,1)+B89 -> 33 | C90: ='27'!M90 -> 99954 Axel D 13/1-20/1 Guest | D90: =IF('27'!N90=0,"",'27'!N90) -> DNK | E90: ='27'!O90 -> 27 | F90: ='27'!P90 -> 209 | G90: ='27'!Q90 -> Double | H90: ='27'!R90 -> 0 | I90: ='27'!S90 -> 0 | K90: ='27'!T90 -> 0 | L90: ='27'!U90 -> 1 | M90: ='27'!V90 -> 2 | O90: ='27'!W90 -> 0 | P90: =IF('27'!X90=0,"",'27'!X90) | Q90: =IF('27'!Y90=0,"",'27'!Y90) | R90: =IF('27'!Z90=0,"",'27'!Z90) -> 0061 | S90: =IF('27'!AA90=0,"",'27'!AA90) -> #N/A
B91: =COUNTA(C91)-IF(C91=0,1)+B90 -> 34 | C91: ='27'!M91 -> 99955 Viktor L 13/1-20/1 Guest | D91: =IF('27'!N91=0,"",'27'!N91) -> DNK | E91: ='27'!O91 -> 27 | F91: ='27'!P91 -> 209 | G91: ='27'!Q91 -> 0 | H91: ='27'!R91 -> 0 | I91: ='27'!S91 -> 0 | K91: ='27'!T91 -> 0 | L91: ='27'!U91 -> 2 | M91: ='27'!V91 -> 0 | O91: ='27'!W91 -> 0 | P91: =IF('27'!X91=0,"",'27'!X91) | Q91: =IF('27'!Y91=0,"",'27'!Y91) | R91: =IF('27'!Z91=0,"",'27'!Z91) -> 0060 | S91: =IF('27'!AA91=0,"",'27'!AA91) -> #N/A
B92: =COUNTA(C92)-IF(C92=0,1)+B91 -> 34 | C92: ='27'!M92 -> 0 | D92: =IF('27'!N92=0,"",'27'!N92) | E92: ='27'!O92 -> 27 | F92: ='27'!P92 -> 209 | G92: ='27'!Q92 -> 0 | H92: ='27'!R92 -> 0 | I92: ='27'!S92 -> 0 | K92: ='27'!T92 -> 0 | L92: ='27'!U92 -> 0 | M92: ='27'!V92 -> 0 | O92: ='27'!W92 -> 0 | P92: =IF('27'!X92=0,"",'27'!X92) | Q92: =IF('27'!Y92=0,"",'27'!Y92) | R92: =IF('27'!Z92=0,"",'27'!Z92) | S92: =IF('27'!AA92=0,"",'27'!AA92) -> #N/A
B93: =COUNTA(C93)-IF(C93=0,1)+B92 -> 35 | C93: ='27'!M93 -> 99956 Albin A 13/1-20/1 Guest | D93: =IF('27'!N93=0,"",'27'!N93) | E93: ='27'!O93 -> 27 | F93: ='27'!P93 -> 210 | G93: ='27'!Q93 -> Double | H93: ='27'!R93 -> 0 | I93: ='27'!S93 -> 0 | K93: ='27'!T93 -> 0 | L93: ='27'!U93 -> 0 | M93: ='27'!V93 -> 2 | O93: ='27'!W93 -> 0 | P93: =IF('27'!X93=0,"",'27'!X93) | Q93: =IF('27'!Y93=0,"",'27'!Y93) | R93: =IF('27'!Z93=0,"",'27'!Z93) | S93: =IF('27'!AA93=0,"",'27'!AA93) -> #N/A
B94: =COUNTA(C94)-IF(C94=0,1)+B93 -> 36 | C94: ='27'!M94 -> 99957 Alfons B 13/1-20/1 Guest | D94: =IF('27'!N94=0,"",'27'!N94) -> DNK | E94: ='27'!O94 -> 27 | F94: ='27'!P94 -> 210 | G94: ='27'!Q94 -> 0 | H94: ='27'!R94 -> 0 | I94: ='27'!S94 -> 0 | K94: ='27'!T94 -> 0 | L94: ='27'!U94 -> 2 | M94: ='27'!V94 -> 0 | O94: ='27'!W94 -> 0 | P94: =IF('27'!X94=0,"",'27'!X94) | Q94: =IF('27'!Y94=0,"",'27'!Y94) | R94: =IF('27'!Z94=0,"",'27'!Z94) -> 0062 | S94: =IF('27'!AA94=0,"",'27'!AA94) -> #N/A
B95: =COUNTA(C95)-IF(C95=0,1)+B94 -> 36 | C95: ='27'!M95 -> 0 | D95: =IF('27'!N95=0,"",'27'!N95) -> DNK | E95: ='27'!O95 -> 27 | F95: ='27'!P95 -> 210 | G95: ='27'!Q95 -> 0 | H95: ='27'!R95 -> 0 | I95: ='27'!S95 -> 0 | K95: ='27'!T95 -> 0 | L95: ='27'!U95 -> 3 | M95: ='27'!V95 -> 0 | O95: ='27'!W95 -> 0 | P95: =IF('27'!X95=0,"",'27'!X95) | Q95: =IF('27'!Y95=0,"",'27'!Y95) | R95: =IF('27'!Z95=0,"",'27'!Z95) -> 0063 | S95: =IF('27'!AA95=0,"",'27'!AA95) -> #N/A
B96: =COUNTA(C96)-IF(C96=0,1)+B95 -> 37 | C96: ='27'!M96 -> 99958 Sam F 13/1-20/1 Guest | D96: =IF('27'!N96=0,"",'27'!N96) -> DNK | E96: ='27'!O96 -> 27 | F96: ='27'!P96 -> 211 | G96: ='27'!Q96 -> Double | H96: ='27'!R96 -> 0 | I96: ='27'!S96 -> 0 | K96: ='27'!T96 -> 0 | L96: ='27'!U96 -> 1 | M96: ='27'!V96 -> 2 | O96: ='27'!W96 -> 0 | P96: =IF('27'!X96=0,"",'27'!X96) | Q96: =IF('27'!Y96=0,"",'27'!Y96) | R96: =IF('27'!Z96=0,"",'27'!Z96) -> 0065 | S96: =IF('27'!AA96=0,"",'27'!AA96) -> #N/A
... B125: =COUNTA(C125)-IF(C125=0,1)+B124 -> 50 | C125: ='27'!M125 -> 0 | D125: =IF('27'!N125=0,"",'27'!N125) -> DNK | E125: ='27'!O125 -> 27 | F125: ='27'!P125 -> 220 | G125: ='27'!Q125 -> 0 | H125: ='27'!R125 -> 0 | I125: ='27'!S125 -> 0 | K125: ='27'!T125 -> 0 | L125: ='27'!U125 -> 3 | M125: ='27'!V125 -> 0 | O125: ='27'!W125 -> 0 | P125: =IF('27'!X125=0,"",'27'!X125) | Q125: =IF('27'!Y125=0,"",'27'!Y125) | R125: =IF('27'!Z125=0,"",'27'!Z125) -> 0871 | S125: =IF('27'!AA125=0,"",'27'!AA125) -> #N/A
B126: =COUNTA(C126)-IF(C126=0,1)+B125 -> #REF! | C126: =#REF! -> #REF! | D126: =IF(#REF!=0,"",#REF!) -> #REF! | E126: =IF(#REF!=0,"",#REF!) -> #REF! | F126: =IF(#REF!=0,"",#REF!) -> #REF! | G126: =#REF! -> #REF! | H126: ='27'!R126 -> 0 | I126: ='27'!S126 -> 0 | K126: ='27'!T126 -> 0 | L126: =#REF! -> #REF! | M126: =#REF! -> #REF! | O126: =#REF! -> #REF! | P126: =IF(#REF!=0,"",#REF!) -> #REF! | Q126: =IF(#REF!=0,"",#REF!) -> #REF! | R126: =IF(#REF!=0,"",#REF!) -> #REF! | S126: =IF(#REF!=0,"",#REF!) -> #REF!
B127: =COUNTA(C127)-IF(C127=0,1)+B126 -> #REF! | C127: =#REF! -> #REF! | D127: =IF(#REF!=0,"",#REF!) -> #REF! | E127: =IF(#REF!=0,"",#REF!) -> #REF! | F127: =IF(#REF!=0,"",#REF!) -> #REF! | G127: ='27'!Q127 -> 0 | H127: ='27'!R127 -> 0 | I127: ='27'!S127 -> 0 | K127: ='27'!T127 -> 0 | L127: =#REF! -> #REF! | M127: =#REF! -> #REF! | O127: =#REF! -> #REF! | P127: =IF(#REF!=0,"",#REF!) -> #REF! | Q127: =IF(#REF!=0,"",#REF!) -> #REF! | R127: =IF(#REF!=0,"",#REF!) -> #REF! | S127: =IF(#REF!=0,"",#REF!) -> #REF!
B128: =COUNTA(C128)-IF(C128=0,1)+B127 -> #REF! | C128: =#REF! -> #REF! | D128: =IF(#REF!=0,"",#REF!) -> #REF! | E128: =IF(#REF!=0,"",#REF!) -> #REF! | F128: =IF(#REF!=0,"",#REF!) -> #REF! | G128: ='27'!Q128 -> 0 | H128: ='27'!R128 -> 0 | I128: ='27'!S128 -> 0 | K128: ='27'!T128 -> 0 | L128: =#REF! -> #REF! | M128: =#REF! -> #REF! | O128: =#REF! -> #REF! | P128: =IF(#REF!=0,"",#REF!) -> #REF! | Q128: =IF(#REF!=0,"",#REF!) -> #REF! | R128: =IF(#REF!=0,"",#REF!) -> #REF! | S128: =IF(#REF!=0,"",#REF!) -> #REF!
...

Sheet Notes
C1: Table | G1: Invent
B3: 226 | C3: 496307 Martin | D3: 29 | E3: 113 | G3: 496307 Martin | H3: 29 | I3: 109 | J3: 3
B4: 215 | C4: 503207 Martin | D4: 29 | E4: 109 | G4: 503207 Martin | H4: 29 | I4: 113 | J4: 3
B6: 231 | C6: 496247 Niklas | D6: 29 | E6: 115 | G6: 496247 Niklas | H6: 29 | I6: 114 | J6: 2
B7: 238 | C7: 464152 Nicklas | D7: 29 | E7: 118 | G7: 464152 Nicklas | H7: 29 | I7: 115 | J7: 2
B9: 240 | C9: 496683 Kenn | D9: 29 | E9: 118 | G9: 496683 Kenn | H9: 29 | I9: 114 | J9: 3
B10: 228 | C10: 508172 Christopher | D10: 29 | E10: 114
B11: 230 | C11: 519832 Anders | D11: 29 | E11: 114
B12: 244 | C12: 519045 Tilde | D12: 29 | E12: 120 | G12: 519045 Tilde | H12: 29 | I12: 117 | J12: 2
B13: 229 | C13: 518229 Simon | D13: 29 | E13: 114 | G13: 518229 Simon | H13: 29 | I13: 118 | J13: 2
B15: 239 | C15: 447403 Jonas | D15: 29 | E15: 118 | G15: 447403 Jonas | H15: 29 | I15: 118 | J15: 1
G16: 447403 Jonas | H16: 29 | I16: 114 | J16: 1
B17: 237 | C17: 514546 Benjamin | D17: 29 | E17: 117 | G17: 514546 Benjamin | H17: 29 | I17: 117 | J17: 3
G18: 514546 Benjamin | H18: 29 | I18: 118 | J18: 3
B19: 263 | C19: 492346 Michael | D19: 29 | E19: 208 | G19: 492346 Michael | H19: 29 | I19: 208 | J19: 3
G20: 492346 Michael | H20: 29 | I20: 203 | J20: 3
B23: 447 | C23: 176046 Bjørn | D23: 31 | E23: 114 | G23: 176046 Bjørn | H23: 31 | I23: 113 | J23: 1
B24: 443 | C24: 397279 Jesper | D24: 31 | E24: 113 | G24: 397279 Jesper | H24: 31 | I24: 114 | J24: 2
B26: 235 | C26: 496313 Kristoffer | D26: 29 | E26: 117 | G26: 496313 Lars | H26: 29 | I26: 120 | J26: 1
B28: 745 | C28: 490977 Jeppe | D28: 35 | E28: 115 | G28: 4909771 Jeppe | H28: 35 | I28: 115 | J28: 2
B30: 701 | C30: 455033 Nikolai | D30: 34 | E30: 220 | G30: 455033 Nikolai | H30: 34 | I30: 217 | J30: 1
B31: 702 | C31: 451389 Mads | D31: 34 | E31: 220 | G31: 451389 Mads | H31: 34 | I31: 217 | J31: 2
G32: 455033 Nikolai | H32: 34 | I32: 220 | J32: 1
G33: 451389 Mads | H33: 34 | I33: 220 | J33: 2
B35: 523 | C35: NSPA - Duran | D35: 32 | E35: 220 | G35: Duran NSPA | H35: 32 | I35: 204 | J35: 2
B36: 508 | C36: NSPA - George | D36: 32 | E36: 201 | G36: George NSPA | H36: 32 | I36: 203 | J36: 1
B37: 522 | C37: NSPA - Henri | D37: 32 | E37: 219 | G37: Henri NSPA | H37: 32 | I37: 216 | J37: 1
B38: 509 | C38: NSPA - Matthew | D38: 32 | E38: 202
G39: Jim NSPA | H39: 32 | I39: 204 | J39: 1

Sheet Data
A1: Name | B1: Code | C1: User | D1: Serial Number | E1: Location | H1: Name | I1: User | J1: Code | K1: Serial Number | L1: Location
A2: 27/1/E1/1 | B2: 6483CE93 | C2: sadmin | D2: key | E2: Accommodation Keys | H2: 452127 | I2: 452127 Sebastian | J2: Bag 0189 | K2: 189 | L2: Laundry Bags in Use
A3: 27/1/E1/2 | B3: D4F4CC93 | C3: sadmin | D3: key | E3: Accommodation Keys | H3: Bag 0824 | I3: sadmin | J3: Bag 0824 | K3: 824 | L3: Unreceived Bags
A4: 27/1/E1/3 | B4: B40DED93 | C4: sadmin | D4: key | E4: Accommodation Keys | H4: 506372 | I4: 506372 Magnus | J4: Bag 0447 | K4: 447 | L4: Laundry Bags in Use
A5: 27/1/E2/1 | B5: 14E0DB93 | C5: sadmin | D5: key | E5: Accommodation Keys | H5: 472536 | I5: 472536 Alexander | J5: Bag 0455 | K5: 455 | L5: Laundry Bags in Use
A6: 27/1/E2/2 | B6: 2413CD93 | C6: sadmin | D6: key | E6: Accommodation Keys | H6: 508884 | I6: 508884 Jes | J6: Bag 0232 | K6: 232 | L6: Laundry Bags in Use
A7: 27/1/E2/3 | B7: 74D8DF93 | C7: sadmin | D7: key | E7: Accommodation Keys | H7: 410103 | I7: 410103 Kasper | J7: Bag 0615 | K7: 615 | L7: Laundry Bags in Use
A8: 27/101/1 | B8: 8408E493 | C8: 99901 Richard | D8: key | E8: Accommodation Keys | H8: 393712 | I8: 393712 Peter | J8: Bag 0620 | K8: 620 | L8: Laundry Bags in Use
A9: 27/101/2 | B9: 743DE893 | D9: key | E9: Accommodation Keys | H9: 534522 | I9: 534522 Michael | J9: Bag 0641 | K9: 641 | L9: Laundry Bags in Use
A10: 27/101/3 | B10: A473CD93 | D10: key | E10: Accommodation Keys | H10: Bag 0305 | I10: sadmin | J10: Bag 0305 | K10: 305 | L10: Laundry Bags Depot
A11: 27/102/1 | B11: A435E293 | C11: 99903 Hakan | D11: key | E11: Accommodation Keys | H11: 439367 | I11: 439367 Malthe | J11: Bag 0724 | K11: 724 | L11: Laundry Bags in Use
A12: 27/102/2 | B12: C487F493 | D12: key | E12: Accommodation Keys | H12: 478336 | I12: 478336 Johannes | J12: Bag 0059 | K12: 59 | L12: Laundry Bags in Use
A13: 27/102/3 | B13: 64E1D593 | D13: key | E13: Accommodation Keys | H13: Bag 0394 | I13: sadmin | J13: Bag 0394 | K13: 394 | L13: Laundry Bags Depot
A14: 27/103/1 | B14: A4B2E193 | C14: 99905 Torbjorn | D14: key | E14: Accommodation Keys | H14: 307201 | I14: 307201 Yoan | J14: Bag 0909 | K14: 909 | L14: Laundry Bags in Use
A15: 27/103/2 | B15: 3416CF93 | D15: key | E15: Accommodation Keys | H15: Bag 0838 | I15: sadmin | J15: Bag 0838 | K15: 838 | L15: Unreceived Bags
A16: 27/103/3 | B16: C456E093 | D16: key | E16: Accommodation Keys | H16: 193022 | I16: 193022 Claus | J16: Bag 0974 | K16: 974 | L16: Laundry Bags in Use
A17: 27/104/1 | B17: 44A5E293 | C17: 99907 Kateryna | D17: key | E17: Accommodation Keys | H17: 194935 | I17: 194935 Karsten | J17: Bag 0047 | K17: 47 | L17: Laundry Bags in Use
A18: 27/104/2 | B18: B4B14194 | D18: key | E18: Accommodation Keys | H18: 397279 | I18: 397279 Jesper | J18: Bag 0545 | K18: 545 | L18: Laundry Bags in Use
A19: 27/104/3 | B19: 140DF093 | D19: key | E19: Accommodation Keys | H19: Bag 0847 | I19: sadmin | J19: Bag 0847 | K19: 847 | L19: Unreceived Bags
A20: 27/105/1 | B20: A4AEF493 | C20: 99909 Bjorn | D20: key | E20: Accommodation Keys | H20: 511788 | I20: 511788 Ghislain | J20: Bag 1011 | K20: 1011 | L20: Laundry Bags in Use
A21: 27/105/2 | B21: A427D093 | D21: key | E21: Accommodation Keys | H21: Bag 0848 | I21: sadmin | J21: Bag 0848 | K21: 848 | L21: Unreceived Bags
A22: 27/105/3 | B22: 248DE193 | D22: key | E22: Accommodation Keys | H22: 431628 | I22: 431628 Marc | J22: Bag 1000 | K22: 1000 | L22: Laundry Bags in Use
A23: 27/106/1 | B23: 842FE293 | C23: 99911 Bjorn | D23: key | E23: Accommodation Keys | H23: 494353 | I23: 494353 Mikkel | J23: Bag 0768 | K23: 768 | L23: Laundry Bags in Use
A24: 27/106/2 | B24: 84B5D293 | D24: key | E24: Accommodation Keys | H24: 495997 | I24: 495997 Sandra | J24: Bag 1104 | K24: 1104 | L24: Laundry Bags in Use
A25: 27/106/3 | B25: A4F5DC93 | D25: key | E25: Accommodation Keys | H25: 495475 | I25: 495475 Stefan | J25: Bag 1024 | K25: 1024 | L25: Laundry Bags in Use
A26: 27/107/1 | B26: 747ECC93 | C26: 99913 Ida | D26: key | E26: Accommodation Keys | H26: 456552 | I26: 456552 Oliver | J26: Bag 0513 | K26: 513 | L26: Laundry Bags in Use
A27: 27/107/2 | B27: 44C74594 | D27: key | E27: Accommodation Keys | H27: 303575 | I27: 303575 Rasmus | J27: Bag 0243 | K27: 243 | L27: Laundry Bags in Use
A28: 27/107/3 | B28: 746FE193 | D28: key | E28: Accommodation Keys | H28: 197679 | I28: 197679 Niels Erik | J28: Bag 0674 | K28: 674 | L28: Laundry Bags in Use
A29: 27/108/1 | B29: 944FE193 | C29: 99914 Maria | D29: key | E29: Accommodation Keys | H29: 171119 | I29: 171119 Olivier | J29: Bag 0820 | K29: 820 | L29: Laundry Bags in Use
A30: 27/108/2 | B30: 34DCEE93 | D30: key | E30: Accommodation Keys | H30: 485435 | I30: 485435 Micki | J30: Bag 0654 | K30: 654 | L30: Laundry Bags in Use
A31: 27/108/3 | B31: 04EED593 | D31: key | E31: Accommodation Keys | H31: 456401 | I31: 456401 Patrick | J31: Bag 0740 | K31: 740 | L31: Laundry Bags in Use
A32: 27/109/1 | B32: E46BD893 | C32: 99915 Rickard | D32: key | E32: Accommodation Keys | H32: Bag 0822 | I32: sadmin | J32: Bag 0822 | K32: 822 | L32: Unreceived Bags
A33: 27/109/2 | B33: 04D23B94 | D33: key | E33: Accommodation Keys | H33: 459106 | I33: 459106 Daniel | J33: Bag 0015 | K33: 15 | L33: Laundry Bags in Use
A34: 27/109/3 | B34: 3484F493 | D34: key | E34: Accommodation Keys | H34: 509424 | I34: 509424 Emil | J34: Bag 0084 | K34: 84 | L34: Laundry Bags in Use
A35: 27/110/1 | B35: 6454CB93 | C35: 99917 Patrik | D35: key | E35: Accommodation Keys | H35: Bag 0454 | I35: sadmin | J35: Bag 0454 | K35: 454 | L35: Unreceived Bags
A36: 27/110/2 | B36: D4BD3794 | D36: key | E36: Accommodation Keys | H36: Bag 0357 | I36: sadmin | J36: Bag 0357 | K36: 357 | L36: Laundry Bags Depot
A37: 27/110/3 | B37: 94D2E493 | D37: key | E37: Accommodation Keys | H37: Bag 0381 | I37: sadmin | J37: Bag 0381 | K37: 381 | L37: Laundry Bags Depot
A38: 27/111/1 | B38: D4763894 | C38: 99919 Jimmy | D38: key | E38: Accommodation Keys | H38: Bag 0063 | I38: sadmin | J38: Bag 0063 | K38: 63 | L38: Laundry Bags Depot
A39: 27/111/2 | B39: E42AE193 | D39: key | E39: Accommodation Keys | H39: 425459 | I39: 425459 Mads | J39: Bag 0885 | K39: 885 | L39: Laundry Bags in Use
A40: 27/111/3 | B40: 6449F493 | D40: key | E40: Accommodation Keys | H40: 501115 | I40: 501115 Villads | J40: Bag 0696 | K40: 696 | L40: Laundry Bags in Use
...

Sheet MEAL CARD
G1: ADDITIONAL KEYS GIVEN | J1: MC | K1: Laundry Tag
A2: Name | B2: Code | C2: User | D2: MC | E2: Bag | G2: 32/205/1 | H2: D47FDD93 | I2: 167039 Jesper | J2: 0368 | K2: 893
A3: 27/101/1 | C3: 99901 | D3: 1001 | E3: 0158 | G3: 32/206/1 | H3: B4E2D093 | I3: 399105 Chris
A4: 27/102/1 | C4: 99903 | D4: 1002 | E4: 0174 | G4: 32/207/1 | H4: 64D0D393 | I4: 443003 Jesper
A5: 27/103/1 | C5: 99905 | D5: 1003 | E5: 0124 | G5: 32/215/1 | H5: 1455E193 | I5: 500640 Philip
A6: 27/104/1 | C6: 99907 | D6: 1004 | E6: 0239 | G6: 32/208/1 | H6: E4454794 | I6: 514113 Abdul
A7: 27/105/1 | C7: 99909 | D7: 1005 | E7: 0301 | G7: 32/203/1 | H7: F46B3894 | I7: 201379 Nikolai Risvange | J7: 0366 | K7: 246
A8: 27/106/1 | C8: 99911 | D8: 1006 | E8: 0233 | G8: 32/204/1 | H8: C4E3CC93 | I8: 485210 Kasper Thomsen | J8: 0365 | K8: 600
A9: 27/107/1 | C9: 99913 | D9: 1007 | E9: 0667 | G9: 32/216/1 | H9: 1463D693 | I9: 171631 Bjarne S. Munk | J9: 0367 | K9: 628
A10: 27/108/1 | C10: 99914 | D10: 1008 | E10: 0032 | G10: 32/217/1 | H10: A4DCDB93 | I10: 304794 Christian Andersen | J10: 0364 | K10: 1094
A11: 27/109/1 | C11: 99915 | D11: 1009 | E11: 0166 | G11: 32/218/1 | H11: 544BDA93 | I11: 225018 Anders Tagge | J11: 0363 | K11: 1058
A12: 27/110/1 | C12: 99917 | D12: 1010 | E12: 0562 | G12: 32/214/1 | I12: 155449 Rene
A13: 27/111/1 | C13: 99919 | D13: 1011 | E13: 0693 | G13: 32/213/1 | I13: 185768 Christian
A14: 27/112/1 | C14: 99920 | D14: 1012 | E14: 0223 | G14: 32/211/1 | I14: 211628/Karsten Falck
A15: 27/113/1 | C15: 99918 | D15: 1013 | E15: 1140
A16: 27/114/1 | C16: 99916 | D16: 1014 | E16: 0145
A17: 27/115/1 | C17: 99912 | D17: 1015 | E17: 0735
A18: 27/116/1 | C18: 99910 | D18: 1016 | E18: 0098
A19: 27/117/1 | C19: 99908 | D19: 1017 | E19: 0193
A20: 27/118/1 | C20: 99906 | D20: 1018 | E20: 0728
A21: 27/119/1 | C21: 99904 | D21: 1019 | E21: 0001
A22: 27/120/1 | C22: 99902 | D22: 1020 | E22: 0213
A23: 27/201/1 | C23: 99921 | D23: 1021 | E23: 0954
A24: 27/202/1 | C24: 99923 | D24: 1022 | E24: 0123
A25: 27/203/1 | C25: 99932 | D25: 1023 | E25: 1178
A26: 27/203/2 | C26: 99933 | D26: 1024 | E26: 1174
... A49: 28/109/1 | C49: 12301 | D49: 1047 | E49: 0216
A50: 28/109/2 | C50: 12302 | D50: 1048 | E50: 0188 | P50: `
A51: 28/110/1 | C51: 12304 | D51: 1049 | E51: 0184
A52: 28/110/2 | C52: 12307 | D52: 1050 | E52: 0990
A53: 28/111/1 | C53: 12001 | D53: 1051 | E53: 0231
A54: 28/112/1 | C54: 12002 | D54: 1052 | E54: 0306
A55: 28/113/1 | C55: 12309 | D55: 1053 | E55: 0964
A56: 28/113/2 | C56: 12306 | D56: 1054 | E56: 1176
A57: 28/114/1 | C57: 12308 | D57: 1055 | E57: 0170
A58: 28/115/1 | C58: 12208 | D58: 1057 | E58: 1182
A59: 28/115/2 | C59: 12209 | D59: 1058 | E59: 0988
A60: 28/116/1 | C60: 12204 | D60: 1059 | E60: 0711
A61: 28/116/2 | C61: 12207 | D61: 1060 | E61: 0010
A62: 28/117/1 | C62: 12111 | D62: 1061 | E62: 0168
...

Sheet Sheet2
A1: 1001
A2: 1002
A3: 1003
A4: 1004
A5: 1005
A6: 1006
A7: 1007
A8: 1008
A9: 1009
A10: 1010
A11: 1011
A12: 1012
... A159: 1159

Sheet Sheet1
A1: 27 | B1: / | C1: 101 | D1: / | E1: 2
A2: 27 | B2: / | C2: 101 | D2: / | E2: 3
A3: 27 | B3: / | C3: 102 | D3: / | E3: 1
A4: 27 | B4: / | C4: 102 | D4: / | E4: 3
A5: 27 | B5: / | C5: 103 | D5: / | E5: 1
A6: 27 | B6: / | C6: 103 | D6: / | E6: 3
A7: 27 | B7: / | C7: 104 | D7: / | E7: 1
A8: 27 | B8: / | C8: 104 | D8: / | E8: 2
A9: 27 | B9: / | C9: 104 | D9: / | E9: 3
A10: 27 | B10: / | C10: 105 | D10: / | E10: 1
A11: 27 | B11: / | C11: 105 | D11: / | E11: 3
A12: 27 | B12: / | C12: 106 | D12: / | E12: 2
... A988: 36 | B988: / | C988: 220 | D988: / | E988: 3

Sheet 27
L2: # | M2: NAME, ID | N2: Nation | O2: Building | P2: ROOM | U2: Placed Beds | X2: Date | AB2: Remarks
C3: Password: 12 | P3: Used | Q3: Single | R3: Double | S3: Triple | T3: Empty | U3: 1 | V3: 2 | W3: 3 | X3: ETA | Y3: ETD | Z3: MC | AA3: L. Bag
C4: Building 27 - 1st floor | M4: =Q4+R4*2+S4*3 -> 83 | P4: =SUM(Q4:S4) -> 40 | Q4: =COUNTIFS(Q6:T125,"=Single") -> 3 | R4: =COUNTIFS(Q6:T125,"=Double") -> 31 | S4: =COUNTIFS(Q6:T125,"=Triple") -> 6 | T4: =COUNTIFS(Q6:T125,"=Empty") -> 0 | U4: =COUNTIFS(V6:W125,"=1") -> 3 | V4: =COUNTIFS(V6:W125,"=2") -> 31 | W4: =COUNTIFS(V6:W125,"=3") -> 6 | Z4: =COUNTA(Z6:Z130) -> 83 | AA4: =COUNTA(AA6:AA130)-SUM(COUNTIF(AA6:AA130,{"#N/A"})) -> 1
B5: Rooms | G5: Rooms | U5: =SUM(V6:W125) -> 83 | V5: b/r | W5: =U4+V4+W4 -> 40
B6: 101 | D6: ETA | E6: ETD | G6: 120 | I6: ETA | J6: ETD | L6: =COUNTA(B7) -> 0 | M6: =C7 -> 99901 Richard | O6: 27 | P6: 101 | Q6: =_xlfn.IFS(COUNTA(B7:B9)=1,"Single",COUNTA(B7:B9)=2,"Double",COUNTA(B7:B9)=3,"Triple",COUNTA(B7:B9)=0,"Empty") -> Double | U6: =B7 -> 0 | V6: =COUNT(B7:B9) -> 2 | X6: =IF(D7=0,"",D7) | Y6: =IF(E7=0,"",E7) | AA6: =VLOOKUP($M:$M,Data!$I:$J,2,FALSE) -> #N/A | AB6: Changed on 18.08
C7: =VLOOKUP("27/101/1",Data!$A$2:$E$1425,3,FALSE) -> 99901 Richard | G7: 1 | H7: =VLOOKUP("27/120/1",Data!$A$2:$E$1425,3,FALSE) -> 99902 Peter | L7: =COUNTA(B8)+L6 -> 1 | M7: =C8 -> 0 | N7: DNK | O7: 27 | P7: 101 | U7: =B8 -> 2 | X7: =IF(D8=0,"",D8) | Y7: =IF(E8=0,"",E8) | Z7: 0002 | AA7: =VLOOKUP($M:$M,Data!$I:$J,2,FALSE) -> #N/A
B8: 2 | C8: =VLOOKUP("27/101/2",Data!$A$2:$E$1425,3,FALSE) -> 0 | H8: =VLOOKUP("27/120/2",Data!$A$2:$E$1425,3,FALSE) -> 0 | L8: =COUNTA(B9)+L7 -> 2 | M8: =C9 -> 0 | N8: DNK | O8: 27 | P8: 101 | U8: =B9 -> 3 | X8: =IF(D9=0,"",D9) | Y8: =IF(E9=0,"",E9) | AA8: =VLOOKUP($M:$M,Data!$I:$J,2,FALSE) -> #N/A
B9: 3 | C9: =VLOOKUP("27/101/3",Data!$A$2:$E$1425,3,FALSE) -> 0 | G9: 3 | H9: =VLOOKUP("27/120/3",Data!$A$2:$E$1425,3,FALSE) -> 0 | L9: =COUNTA(B11)+L8 -> 3 | M9: =C11 -> 99903 Hakan | N9: DNK | O9: 27 | P9: 102 | Q9: =_xlfn.IFS(COUNTA(B11:B13)=1,"Single",COUNTA(B11:B13)=2,"Double",COUNTA(B11:B13)=3,"Triple",COUNTA(B11:B13)=0,"Empty") -> Double | U9: =B11 -> 1 | V9: =COUNT(B11:B13) -> 2 | X9: =IF(D11=0,"",D11) | Y9: =IF(E11=0,"",E11) | Z9: 0004 | AA9: =VLOOKUP($M:$M,Data!$I:$J,2,FALSE) -> #N/A
B10: 102 | D10: ETA | E10: ETD | G10: 119 | I10: ETA | J10: ETD | L10: =COUNTA(B12)+L9 -> 3 | M10: =C12 -> 0 | O10: 27 | P10: 102 | U10: =B12 -> 0 | X10: =IF(D12=0,"",D12) | Y10: =IF(E12=0,"",E12) | AA10: =VLOOKUP($M:$M,Data!$I:$J,2,FALSE) -> #N/A
B11: 1 | C11: =VLOOKUP("27/102/1",Data!$A$2:$E$1425,3,FALSE) -> 99903 Hakan | G11: 1 | H11: =VLOOKUP("27/119/1",Data!$A$2:$E$1425,3,FALSE) -> 99904 Philip | L11: =COUNTA(B13)+L10 -> 4 | M11: =C13 -> 0 | N11: DNK | O11: 27 | P11: 102 | U11: =B13 -> 3 | X11: =IF(D13=0,"",D13) | Y11: =IF(E13=0,"",E13) | Z11: 0005 | AA11: =VLOOKUP($M:$M,Data!$I:$J,2,FALSE) -> #N/A
C12: =VLOOKUP("27/102/2",Data!$A$2:$E$1425,3,FALSE) -> 0 | G12: 2 | H12: =VLOOKUP("27/119/2",Data!$A$2:$E$1425,3,FALSE) -> 0 | L12: =COUNTA(B15)+L11 -> 5 | M12: =C15 -> 99905 Torbjorn | N12: DNK | O12: 27 | P12: 103 | Q12: =_xlfn.IFS(COUNTA(B15:B17)=1,"Single",COUNTA(B15:B17)=2,"Double",COUNTA(B15:B17)=3,"Triple",COUNTA(B15:B17)=0,"Empty") -> Double | U12: =B15 -> 1 | V12: =COUNT(B15:B17) -> 2 | X12: =IF(D15=0,"",D15) | Y12: =IF(E15=0,"",E15) | Z12: 0006 | AA12: Bag 0167
B13: 3 | C13: =VLOOKUP("27/102/3",Data!$A$2:$E$1425,3,FALSE) -> 0 | G13: 3 | H13: =VLOOKUP("27/119/3",Data!$A$2:$E$1425,3,FALSE) -> 0 | L13: =COUNTA(B16)+L12 -> 5 | M13: =C16 -> 0 | O13: 27 | P13: 103 | U13: =B16 -> 0 | X13: =IF(D16=0,"",D16) | Y13: =IF(E16=0,"",E16) | AA13: =VLOOKUP($M:$M,Data!$I:$J,2,FALSE) -> #N/A
B14: 103 | D14: ETA | E14: ETD | G14: 118 | I14: ETA | J14: ETD | L14: =COUNTA(B17)+L13 -> 6 | M14: =C17 -> 0 | N14: DNK | O14: 27 | P14: 103 | U14: =B17 -> 3 | X14: =IF(D17=0,"",D17) | Y14: =IF(E17=0,"",E17) | Z14: 0007 | AA14: =VLOOKUP($M:$M,Data!$I:$J,2,FALSE) -> #N/A
B15: 1 | C15: =VLOOKUP("27/103/1",Data!$A$2:$E$1425,3,FALSE) -> 99905 Torbjorn | G15: 1 | H15: =VLOOKUP("27/118/1",Data!$A$2:$E$1425,3,FALSE) -> 99906 Christoffer | L15: =COUNTA(B19)+L14 -> 7 | M15: =C19 -> 99907 Kateryna | N15: DNK | O15: 27 | P15: 104 | Q15: =_xlfn.IFS(COUNTA(B19:B21)=1,"Single",COUNTA(B19:B21)=2,"Double",COUNTA(B19:B21)=3,"Triple",COUNTA(B19:B21)=0,"Empty") -> Triple | U15: =B19 -> 1 | V15: =COUNT(B19:B21) -> 3 | X15: =IF(D19=0,"",D19) | Y15: =IF(E19=0,"",E19) | Z15: 0008 | AA15: =VLOOKUP($M:$M,Data!$I:$J,2,FALSE) -> #N/A
C16: =VLOOKUP("27/103/2",Data!$A$2:$E$1425,3,FALSE) -> 0 | G16: 2 | H16: =VLOOKUP("27/118/2",Data!$A$2:$E$1425,3,FALSE) -> 0 | L16: =COUNTA(B20)+L15 -> 8 | M16: =C20 -> 0 | N16: DNK | O16: 27 | P16: 104 | U16: =B20 -> 2 | X16: =IF(D20=0,"",D20) | Y16: =IF(E20=0,"",E20) | Z16: 0010 | AA16: =VLOOKUP($M:$M,Data!$I:$J,2,FALSE) -> #N/A
B17: 3 | C17: =VLOOKUP("27/103/3",Data!$A$2:$E$1425,3,FALSE) -> 0 | G17: 3 | H17: =VLOOKUP("27/118/3",Data!$A$2:$E$1425,3,FALSE) -> 0 | L17: =COUNTA(B21)+L16 -> 9 | M17: =C21 -> 0 | N17: DNK | O17: 27 | P17: 104 | U17: =B21 -> 3 | X17: =IF(D21=0,"",D21) | Y17: =IF(E21=0,"",E21) | Z17: 0009 | AA17: =VLOOKUP($M:$M,Data!$I:$J,2,FALSE) -> #N/A
B18: 104 | D18: ETA | E18: ETD | G18: 117 | I18: ETA | J18: ETD | L18: =COUNTA(B23)+L17 -> 10 | M18: =C23 -> 99909 Bjorn | N18: DNK | O18: 27 | P18: 105 | Q18: =_xlfn.IFS(COUNTA(B23:B25)=1,"Single",COUNTA(B23:B25)=2,"Double",COUNTA(B23:B25)=3,"Triple",COUNTA(B23:B25)=0,"Empty") -> Double | U18: =B23 -> 1 | V18: =COUNT(B23:B25) -> 2 | X18: =IF(D23=0,"",D23) | Y18: =IF(E23=0,"",E23) | Z18: 0011 | AA18: =VLOOKUP($M:$M,Data!$I:$J,2,FALSE) -> #N/A
B19: 1 | C19: =VLOOKUP("27/104/1",Data!$A$2:$E$1425,3,FALSE) -> 99907 Kateryna | H19: =VLOOKUP("27/117/1",Data!$A$2:$E$1425,3,FALSE) -> 99908 Frida | L19: =COUNTA(B24)+L18 -> 10 | M19: =C24 -> 0 | O19: 27 | P19: 105 | U19: =B24 -> 0 | X19: =IF(D24=0,"",D24) | Y19: =IF(E24=0,"",E24) | AA19: =VLOOKUP($M:$M,Data!$I:$J,2,FALSE) -> #N/A
B20: 2 | C20: =VLOOKUP("27/104/2",Data!$A$2:$E$1425,3,FALSE) -> 0 | G20: 2 | H20: =VLOOKUP("27/117/2",Data!$A$2:$E$1425,3,FALSE) -> 0 | L20: =COUNTA(B25)+L19 -> 11 | M20: =C25 -> 0 | N20: DNK | O20: 27 | P20: 105 | U20: =B25 -> 3 | X20: =IF(D25=0,"",D25) | Y20: =IF(E25=0,"",E25) | Z20: 0012 | AA20: =VLOOKUP($M:$M,Data!$I:$J,2,FALSE) -> #N/A
B21: 3 | C21: =VLOOKUP("27/104/3",Data!$A$2:$E$1425,3,FALSE) -> 0 | G21: 3 | H21: =VLOOKUP("27/117/3",Data!$A$2:$E$1425,3,FALSE) -> 0 | L21: =COUNTA(B27)+L20 -> 11 | M21: =C27 -> 99911 Bjorn | O21: 27 | P21: 106 | Q21: =_xlfn.IFS(COUNTA(B27:B29)=1,"Single",COUNTA(B27:B29)=2,"Double",COUNTA(B27:B29)=3,"Triple",COUNTA(B27:B29)=0,"Empty") -> Double | U21: =B27 -> 0 | V21: =COUNT(B27:B29) -> 2 | X21: =IF(D27=0,"",D27) | Y21: =IF(E27=0,"",E27) | AA21: =VLOOKUP($M:$M,Data!$I:$J,2,FALSE) -> #N/A
B22: 105 | D22: ETA | E22: ETD | G22: 116 | I22: ETA | J22: ETD | L22: =COUNTA(B28)+L21 -> 12 | M22: =C28 -> 0 | N22: DNK | O22: 27 | P22: 106 | U22: =B28 -> 2 | X22: =IF(D28=0,"",D28) | Y22: =IF(E28=0,"",E28) | Z22: 0013 | AA22: =VLOOKUP($M:$M,Data!$I:$J,2,FALSE) -> #N/A
B23: 1 | C23: =VLOOKUP("27/105/1",Data!$A$2:$E$1425,3,FALSE) -> 99909 Bjorn | G23: 1 | H23: =VLOOKUP("27/116/1",Data!$A$2:$E$1425,3,FALSE) -> 99910 Roger | L23: =COUNTA(B29)+L22 -> 13 | M23: =C29 -> 0 | N23: DNK | O23: 27 | P23: 106 | U23: =B29 -> 3 | X23: =IF(D29=0,"",D29) | Y23: =IF(E29=0,"",E29) | Z23: 0014 | AA23: =VLOOKUP($M:$M,Data!$I:$J,2,FALSE) -> #N/A
C24: =VLOOKUP("27/105/2",Data!$A$2:$E$1425,3,FALSE) -> 0 | H24: =VLOOKUP("27/116/2",Data!$A$2:$E$1425,3,FALSE) -> 0 | L24: =COUNTA(B31)+L23 -> 14 | M24: =C31 -> 99913 Ida | N24: DNK | O24: 27 | P24: 107 | Q24: =_xlfn.IFS(COUNTA(B31:B33)=1,"Single",COUNTA(B31:B33)=2,"Double",COUNTA(B31:B33)=3,"Triple",COUNTA(B31:B33)=0,"Empty") -> Double | U24: =B31 -> 1 | V24: =COUNT(B31:B33) -> 2 | X24: =IF(D31=0,"",D31) | Y24: =IF(E31=0,"",E31) | Z24: 0016 | AA24: =VLOOKUP($M:$M,Data!$I:$J,2,FALSE) -> #N/A
B25: 3 | C25: =VLOOKUP("27/105/3",Data!$A$2:$E$1425,3,FALSE) -> 0 | G25: 3 | H25: =VLOOKUP("27/116/3",Data!$A$2:$E$1425,3,FALSE) -> 0 | L25: =COUNTA(B32)+L24 -> 15 | M25: =C32 -> 0 | N25: DNK | O25: 27 | P25: 107 | U25: =B32 -> 2 | X25: =IF(D32=0,"",D32) | Y25: =IF(E32=0,"",E32) | Z25: 0015 | AA25: =VLOOKUP($M:$M,Data!$I:$J,2,FALSE) -> #N/A
B26: 106 | D26: ETA | E26: ETD | G26: Drying room | L26: =COUNTA(B33)+L25 -> 15 | M26: =C33 -> 0 | O26: 27 | P26: 107 | U26: =B33 -> 0 | X26: =IF(D33=0,"",D33) | Y26: =IF(E33=0,"",E33) | AA26: =VLOOKUP($M:$M,Data!$I:$J,2,FALSE) -> #N/A
C27: =VLOOKUP("27/106/1",Data!$A$2:$E$1425,3,FALSE) -> 99911 Bjorn | L27: =COUNTA(B35)+L26 -> 15 | M27: =C35 -> 99914 Maria | O27: 27 | P27: 108 | Q27: =_xlfn.IFS(COUNTA(B35:B37)=1,"Single",COUNTA(B35:B37)=2,"Double",COUNTA(B35:B37)=3,"Triple",COUNTA(B35:B37)=0,"Empty") -> Double | U27: =B35 -> 0 | V27: =COUNT(B35:B37) -> 2 | X27: =IF(D35=0,"",D35) | Y27: =IF(E35=0,"",E35) | AA27: =VLOOKUP($M:$M,Data!$I:$J,2,FALSE) -> #N/A
B28: 2 | C28: =VLOOKUP("27/106/2",Data!$A$2:$E$1425,3,FALSE) -> 0 | L28: =COUNTA(B36)+L27 -> 16 | M28: =C36 -> 0 | N28: DNK | O28: 27 | P28: 108 | U28: =B36 -> 2 | X28: =IF(D36=0,"",D36) | Y28: =IF(E36=0,"",E36) | Z28: 0018 | AA28: =VLOOKUP($M:$M,Data!$I:$J,2,FALSE) -> #N/A
B29: 3 | C29: =VLOOKUP("27/106/3",Data!$A$2:$E$1425,3,FALSE) -> 0 | L29: =COUNTA(B37)+L28 -> 17 | M29: =C37 -> 0 | N29: DNK | O29: 27 | P29: 108 | U29: =B37 -> 3 | X29: =IF(D37=0,"",D37) | Y29: =IF(E37=0,"",E37) | Z29: 0017 | AA29: =VLOOKUP($M:$M,Data!$I:$J,2,FALSE) -> #N/A
B30: 107 | D30: ETA | E30: ETD | L30: =COUNTA(B39)+L29 -> 18 | M30: =C39 -> 99915 Rickard | N30: DNK | O30: 27 | P30: 109 | Q30: =_xlfn.IFS(COUNTA(B39:B41)=1,"Single",COUNTA(B39:B41)=2,"Double",COUNTA(B39:B41)=3,"Triple",COUNTA(B39:B41)=0,"Empty") -> Double | U30: =B39 -> 1 | V30: =COUNT(B39:B41) -> 2 | X30: =IF(D39=0,"",D39) | Y30: =IF(E39=0,"",E39) | Z30: 0019 | AA30: =VLOOKUP($M:$M,Data!$I:$J,2,FALSE) -> #N/A
B31: 1 | C31: =VLOOKUP("27/107/1",Data!$A$2:$E$1425,3,FALSE) -> 99913 Ida | L31: =COUNTA(B40)+L30 -> 19 | M31: =C40 -> 0 | N31: DNK | O31: 27 | P31: 109 | U31: =B40 -> 2 | X31: =IF(D40=0,"",D40) | Y31: =IF(E40=0,"",E40) | Z31: 0020 | AA31: =VLOOKUP($M:$M,Data!$I:$J,2,FALSE) -> #N/A
B32: 2 | C32: =VLOOKUP("27/107/2",Data!$A$2:$E$1425,3,FALSE) -> 0 | L32: =COUNTA(B41)+L31 -> 19 | M32: =C41 -> 0 | O32: 27 | P32: 109 | U32: =B41 -> 0 | X32: =IF(D41=0,"",D41) | Y32: =IF(E41=0,"",E41) | AA32: =VLOOKUP($M:$M,Data!$I:$J,2,FALSE) -> #N/A
C33: =VLOOKUP("27/107/3",Data!$A$2:$E$1425,3,FALSE) -> 0 | L33: =COUNTA(B43)+L32 -> 20 | M33: =C43 -> 99917 Patrik | N33: DNK | O33: 27 | P33: 110 | Q33: =_xlfn.IFS(COUNTA(B43:B45)=1,"Single",COUNTA(B43:B45)=2,"Double",COUNTA(B43:B45)=3,"Triple",COUNTA(B43:B45)=0,"Empty") -> Double | U33: =B43 -> 1 | V33: =COUNT(B43:B45) -> 2 | X33: =IF(D43=0,"",D43) | Y33: =IF(E43=0,"",E43) | Z33: 0022 | AA33: =VLOOKUP($M:$M,Data!$I:$J,2,FALSE) -> #N/A
B34: 108 | D34: ETA | E34: ETD | G34: 115 | I34: ETA | J34: ETD | L34: =COUNTA(B44)+L33 -> 21 | M34: =C44 -> 0 | N34: DNK | O34: 27 | P34: 110 | U34: =B44 -> 2 | X34: =IF(D44=0,"",D44) | Y34: =IF(E44=0,"",E44) | Z34: 0021 | AA34: =VLOOKUP($M:$M,Data!$I:$J,2,FALSE) -> #N/A
C35: =VLOOKUP("27/108/1",Data!$A$2:$E$1425,3,FALSE) -> 99914 Maria | G35: 1 | H35: =VLOOKUP("27/115/1",Data!$A$2:$E$1425,3,FALSE) -> 99912 Peter | L35: =COUNTA(B45)+L34 -> 21 | M35: =C45 -> 0 | O35: 27 | P35: 110 | U35: =B45 -> 0 | X35: =IF(D45=0,"",D45) | Y35: =IF(E45=0,"",E45) | AA35: =VLOOKUP($M:$M,Data!$I:$J,2,FALSE) -> #N/A
B36: 2 | C36: =VLOOKUP("27/108/2",Data!$A$2:$E$1425,3,FALSE) -> 0 | G36: 2 | H36: =VLOOKUP("27/115/2",Data!$A$2:$E$1425,3,FALSE) -> 0 | L36: =COUNTA(B47)+L35 -> 22 | M36: =C47 -> 99919 Jimmy | N36: DNK | O36: 27 | P36: 111 | Q36: =_xlfn.IFS(COUNTA(B47:B49)=1,"Single",COUNTA(B47:B49)=2,"Double",COUNTA(B47:B49)=3,"Triple",COUNTA(B47:B49)=0,"Empty") -> Double | U36: =B47 -> 1 | V36: =COUNT(B47:B49) -> 2 | X36: =IF(D47=0,"",D47) | Y36: =IF(E47=0,"",E47) | Z36: 0023 | AA36: =VLOOKUP($M:$M,Data!$I:$J,2,FALSE) -> #N/A
B37: 3 | C37: =VLOOKUP("27/108/3",Data!$A$2:$E$1425,3,FALSE) -> 0 | G37: 3 | H37: =VLOOKUP("27/115/3",Data!$A$2:$E$1425,3,FALSE) -> 0 | L37: =COUNTA(B48)+L36 -> 23 | M37: =C48 -> 0 | N37: DNK | O37: 27 | P37: 111 | U37: =B48 -> 2 | X37: =IF(D48=0,"",D48) | Y37: =IF(E48=0,"",E48) | Z37: 0024 | AA37: =VLOOKUP($M:$M,Data!$I:$J,2,FALSE) -> #N/A
B38: 109 | D38: ETA | E38: ETD | G38: 114 | I38: ETA | J38: ETD | L38: =COUNTA(B49)+L37 -> 23 | M38: =C49 -> 0 | O38: 27 | P38: 111 | U38: =B49 -> 0 | X38: =IF(D49=0,"",D49) | Y38: =IF(E49=0,"",E49) | AA38: =VLOOKUP($M:$M,Data!$I:$J,2,FALSE) -> #N/A
B39: 1 | C39: =VLOOKUP("27/109/1",Data!$A$2:$E$1425,3,FALSE) -> 99915 Rickard | H39: =VLOOKUP("27/114/1",Data!$A$2:$E$1425,3,FALSE) -> 99916 Johan | L39: =COUNTA(G47)+L38 -> 24 | M39: =H47 -> 99920 Adam | N39: DNK | O39: 27 | P39: 112 | Q39: =_xlfn.IFS(COUNTA(G47:G49)=1,"Single",COUNTA(G47:G49)=2,"Double",COUNTA(G47:G49)=3,"Triple",COUNTA(G47:G49)=0,"Empty") -> Double | U39: =G47 -> 1 | V39: =COUNT(G47:G49) -> 2 | X39: =IF(I47=0,"",I47) | Y39: =IF(J47=0,"",J47) | Z39: 0025 | AA39: =VLOOKUP($M:$M,Data!$I:$J,2,FALSE) -> #N/A
B40: 2 | C40: =VLOOKUP("27/109/2",Data!$A$2:$E$1425,3,FALSE) -> 0 | G40: 2 | H40: =VLOOKUP("27/114/2",Data!$A$2:$E$1425,3,FALSE) -> 0 | L40: =COUNTA(G48)+L39 -> 24 | M40: =H48 -> 0 | N40: DNK | O40: 27 | P40: 112 | U40: =G48 -> 0 | X40: =IF(I48=0,"",I48) | Y40: =IF(J48=0,"",J48) | Z40: 0026 | AA40: =VLOOKUP($M:$M,Data!$I:$J,2,FALSE) -> #N/A
C41: =VLOOKUP("27/109/3",Data!$A$2:$E$1425,3,FALSE) -> 0 | G41: 3 | H41: =VLOOKUP("27/114/3",Data!$A$2:$E$1425,3,FALSE) -> 0 | L41: =COUNTA(G49)+L40 -> 25 | M41: =H49 -> 0 | O41: 27 | P41: 112 | U41: =G49 -> 3 | X41: =IF(I49=0,"",I49) | Y41: =IF(J49=0,"",J49) | AA41: =VLOOKUP($M:$M,Data!$I:$J,2,FALSE) -> #N/A
...

Sheet 28
L2: # | M2: NAME, ID | N2: Nation | O2: Building | P2: ROOM | U2: Placed Beds | X2: Date | AB2: Remarks
C3: Password: 12 | P3: Used | Q3: Single | R3: Double | S3: Triple | T3: Empty | U3: 1 | V3: 2 | W3: 3 | X3: ETA | Y3: ETD | Z3: MC | AA3: L. Bag
C4: Building 28 - 1st floor | M4: =Q4+R4*2+S4*3 -> 107 | P4: =SUM(Q4:S4) -> 40 | Q4: =COUNTIFS(Q6:T125,"=Single") -> 0 | R4: =COUNTIFS(Q6:T125,"=Double") -> 13 | S4: =COUNTIFS(Q6:T125,"=Triple") -> 27 | T4: =COUNTIFS(Q6:T125,"=Empty") -> 0 | U4: =COUNTIFS(V6:W125,"=1") -> 0 | V4: =COUNTIFS(V6:W125,"=2") -> 13 | W4: =COUNTIFS(V6:W125,"=3") -> 27 | Z4: =COUNTA(Z6:Z130) -> 106 | AA4: =COUNTA(AA6:AA130)-SUM(COUNTIF(AA6:AA130,{"#N/A"})) -> 0
B5: Rooms | G5: Rooms | U5: =SUM(V6:W125) -> 107 | V5: b/r | W5: =U4+V4+W4 -> 40
B6: 101 | D6: ETA | E6: ETD | G6: 120 | I6: ETA | J6: ETD | L6: =COUNTA(B7) -> 1 | M6: =C7 -> 10002 NILS | N6: DNK | O6: 28 | P6: 101 | Q6: =_xlfn.IFS(COUNTA(B7:B9)=1,"Single",COUNTA(B7:B9)=2,"Double",COUNTA(B7:B9)=3,"Triple",COUNTA(B7:B9)=0,"Empty") -> Triple | U6: =B7 -> 1 | V6: =COUNT(B7:B9) -> 3 | X6: =IF(D7=0,"",D7) | Y6: =IF(E7=0,"",E7) | Z6: 0086 | AA6: =VLOOKUP($M:$M,Data!$I:$J,2,FALSE) -> #N/A
B7: 1 | C7: =VLOOKUP("28/101/1",Data!$A$2:$E$1425,3,FALSE) -> 10002 NILS | G7: 1 | H7: =VLOOKUP("28/120/1",Data!$A$2:$E$1425,3,FALSE) -> 10003 JEFF | L7: =COUNTA(B8)+L6 -> 2 | M7: =C8 -> 0 | N7: DNK | O7: 28 | P7: 101 | U7: =B8 -> 2 | X7: =IF(D8=0,"",D8) | Y7: =IF(E8=0,"",E8) | Z7: 0087 | AA7: =VLOOKUP($M:$M,Data!$I:$J,2,FALSE) -> #N/A
B8: 2 | C8: =VLOOKUP("28/101/2",Data!$A$2:$E$1425,3,FALSE) -> 0 | G8: 2 | H8: =VLOOKUP("28/120/2",Data!$A$2:$E$1425,3,FALSE) -> 0 | L8: =COUNTA(B9)+L7 -> 3 | M8: =C9 -> 0 | N8: DNK | O8: 28 | P8: 101 | U8: =B9 -> 3 | X8: =IF(D9=0,"",D9) | Y8: =IF(E9=0,"",E9) | Z8: 0088 | AA8: =VLOOKUP($M:$M,Data!$I:$J,2,FALSE) -> #N/A
B9: 3 | C9: =VLOOKUP("28/101/3",Data!$A$2:$E$1425,3,FALSE) -> 0 | G9: 3 | H9: =VLOOKUP("28/120/3",Data!$A$2:$E$1425,3,FALSE) -> 0 | L9: =COUNTA(B11)+L8 -> 4 | M9: =C11 -> 12101 SIMON | N9: DNK | O9: 28 | P9: 102 | Q9: =_xlfn.IFS(COUNTA(B11:B13)=1,"Single",COUNTA(B11:B13)=2,"Double",COUNTA(B11:B13)=3,"Triple",COUNTA(B11:B13)=0,"Empty") -> Triple | U9: =B11 -> 1 | V9: =COUNT(B11:B13) -> 3 | X9: =IF(D11=0,"",D11) | Y9: =IF(E11=0,"",E11) | Z9: 0089 | AA9: =VLOOKUP($M:$M,Data!$I:$J,2,FALSE) -> #N/A
B10: 102 | D10: ETA | E10: ETD | G10: 119 | I10: ETA | J10: ETD | L10: =COUNTA(B12)+L9 -> 5 | M10: =C12 -> 12102 NILS | N10: DNK | O10: 28 | P10: 102 | U10: =B12 -> 2 | X10: =IF(D12=0,"",D12) | Y10: =IF(E12=0,"",E12) | Z10: 0090 | AA10: =VLOOKUP($M:$M,Data!$I:$J,2,FALSE) -> #N/A
B11: 1 | C11: =VLOOKUP("28/102/1",Data!$A$2:$E$1425,3,FALSE) -> 12101 SIMON | G11: 1 | H11: =VLOOKUP("28/119/1",Data!$A$2:$E$1425,3,FALSE) -> 12104 ALBIN | L11: =COUNTA(B13)+L10 -> 6 | M11: =C13 -> 0 | N11: DNK | O11: 28 | P11: 102 | U11: =B13 -> 3 | X11: =IF(D13=0,"",D13) | Y11: =IF(E13=0,"",E13) | Z11: 0091 | AA11: =VLOOKUP($M:$M,Data!$I:$J,2,FALSE) -> #N/A
B12: 2 | C12: =VLOOKUP("28/102/2",Data!$A$2:$E$1425,3,FALSE) -> 12102 NILS | G12: 2 | H12: =VLOOKUP("28/119/2",Data!$A$2:$E$1425,3,FALSE) -> 12105 MAX | L12: =COUNTA(B15)+L11 -> 7 | M12: =C15 -> 12201 JESPER | N12: DNK | O12: 28 | P12: 103 | Q12: =_xlfn.IFS(COUNTA(B15:B17)=1,"Single",COUNTA(B15:B17)=2,"Double",COUNTA(B15:B17)=3,"Triple",COUNTA(B15:B17)=0,"Empty") -> Triple | U12: =B15 -> 1 | V12: =COUNT(B15:B17) -> 3 | X12: =IF(D15=0,"",D15) | Y12: =IF(E15=0,"",E15) | Z12: 0092 | AA12: =VLOOKUP($M:$M,Data!$I:$J,2,FALSE) -> #N/A
B13: 3 | C13: =VLOOKUP("28/102/3",Data!$A$2:$E$1425,3,FALSE) -> 0 | G13: 3 | H13: =VLOOKUP("28/119/3",Data!$A$2:$E$1425,3,FALSE) -> 0 | L13: =COUNTA(B16)+L12 -> 8 | M13: =C16 -> 12202 ADAM | N13: DNK | O13: 28 | P13: 103 | U13: =B16 -> 2 | X13: =IF(D16=0,"",D16) | Y13: =IF(E16=0,"",E16) | Z13: 0093 | AA13: =VLOOKUP($M:$M,Data!$I:$J,2,FALSE) -> #N/A
B14: 103 | D14: ETA | E14: ETD | G14: 118 | I14: ETA | J14: ETD | L14: =COUNTA(B17)+L13 -> 9 | M14: =C17 -> 0 | N14: DNK | O14: 28 | P14: 103 | U14: =B17 -> 3 | X14: =IF(D17=0,"",D17) | Y14: =IF(E17=0,"",E17) | Z14: 0094 | AA14: =VLOOKUP($M:$M,Data!$I:$J,2,FALSE) -> #N/A
B15: 1 | C15: =VLOOKUP("28/103/1",Data!$A$2:$E$1425,3,FALSE) -> 12201 JESPER | G15: 1 | H15: =VLOOKUP("28/118/1",Data!$A$2:$E$1425,3,FALSE) -> 12103 FREDRIK | L15: =COUNTA(B19)+L14 -> 10 | M15: =C19 -> 12107 JAKOB | N15: DNK | O15: 28 | P15: 104 | Q15: =_xlfn.IFS(COUNTA(B19:B21)=1,"Single",COUNTA(B19:B21)=2,"Double",COUNTA(B19:B21)=3,"Triple",COUNTA(B19:B21)=0,"Empty") -> Triple | U15: =B19 -> 1 | V15: =COUNT(B19:B21) -> 3 | X15: =IF(D19=0,"",D19) | Y15: =IF(E19=0,"",E19) | Z15: 0095 | AA15: =VLOOKUP($M:$M,Data!$I:$J,2,FALSE) -> #N/A
B16: 2 | C16: =VLOOKUP("28/103/2",Data!$A$2:$E$1425,3,FALSE) -> 12202 ADAM | G16: 2 | H16: =VLOOKUP("28/118/2",Data!$A$2:$E$1425,3,FALSE) -> 0 | L16: =COUNTA(B20)+L15 -> 11 | M16: =C20 -> 12108 JESPER | N16: DNK | O16: 28 | P16: 104 | U16: =B20 -> 2 | X16: =IF(D20=0,"",D20) | Y16: =IF(E20=0,"",E20) | Z16: 0096 | AA16: =VLOOKUP($M:$M,Data!$I:$J,2,FALSE) -> #N/A
B17: 3 | C17: =VLOOKUP("28/103/3",Data!$A$2:$E$1425,3,FALSE) -> 0 | G17: 3 | H17: =VLOOKUP("28/118/3",Data!$A$2:$E$1425,3,FALSE) -> 0 | L17: =COUNTA(B21)+L16 -> 12 | M17: =C21 -> 0 | N17: DNK | O17: 28 | P17: 104 | U17: =B21 -> 3 | X17: =IF(D21=0,"",D21) | Y17: =IF(E21=0,"",E21) | Z17: 0847 | AA17: =VLOOKUP($M:$M,Data!$I:$J,2,FALSE) -> #N/A
B18: 104 | D18: ETA | E18: ETD | G18: 117 | I18: ETA | J18: ETD | L18: =COUNTA(B23)+L17 -> 13 | M18: =C23 -> 12109 THERRAPHAN | N18: DNK | O18: 28 | P18: 105 | Q18: =_xlfn.IFS(COUNTA(B23:B25)=1,"Single",COUNTA(B23:B25)=2,"Double",COUNTA(B23:B25)=3,"Triple",COUNTA(B23:B25)=0,"Empty") -> Triple | U18: =B23 -> 1 | V18: =COUNT(B23:B25) -> 3 | X18: =IF(D23=0,"",D23) | Y18: =IF(E23=0,"",E23) | Z18: 0098 | AA18: =VLOOKUP($M:$M,Data!$I:$J,2,FALSE) -> #N/A
B19: 1 | C19: =VLOOKUP("28/104/1",Data!$A$2:$E$1425,3,FALSE) -> 12107 JAKOB | G19: 1 | H19: =VLOOKUP("28/117/1",Data!$A$2:$E$1425,3,FALSE) -> 12111 OSCAR | L19: =COUNTA(B24)+L18 -> 14 | M19: =C24 -> 12110 ALEXANDER | N19: DNK | O19: 28 | P19: 105 | U19: =B24 -> 2 | X19: =IF(D24=0,"",D24) | Y19: =IF(E24=0,"",E24) | Z19: 0099 | AA19: =VLOOKUP($M:$M,Data!$I:$J,2,FALSE) -> #N/A
B20: 2 | C20: =VLOOKUP("28/104/2",Data!$A$2:$E$1425,3,FALSE) -> 12108 JESPER | G20: 2 | H20: =VLOOKUP("28/117/2",Data!$A$2:$E$1425,3,FALSE) -> 12106 OTTO | L20: =COUNTA(B25)+L19 -> 15 | M20: =C25 -> 0 | N20: DNK | O20: 28 | P20: 105 | U20: =B25 -> 3 | X20: =IF(D25=0,"",D25) | Y20: =IF(E25=0,"",E25) | Z20: 0100 | AA20: =VLOOKUP($M:$M,Data!$I:$J,2,FALSE) -> #N/A
B21: 3 | C21: =VLOOKUP("28/104/3",Data!$A$2:$E$1425,3,FALSE) -> 0 | H21: =VLOOKUP("28/117/3",Data!$A$2:$E$1425,3,FALSE) -> 0 | L21: =COUNTA(B27)+L20 -> 16 | M21: =C27 -> 12203 EMIL | N21: DNK | O21: 28 | P21: 106 | Q21: =_xlfn.IFS(COUNTA(B27:B29)=1,"Single",COUNTA(B27:B29)=2,"Double",COUNTA(B27:B29)=3,"Triple",COUNTA(B27:B29)=0,"Empty") -> Triple | U21: =B27 -> 1 | V21: =COUNT(B27:B29) -> 3 | X21: =IF(D27=0,"",D27) | Y21: =IF(E27=0,"",E27) | Z21: 0101 | AA21: =VLOOKUP($M:$M,Data!$I:$J,2,FALSE) -> #N/A
B22: 105 | D22: ETA | E22: ETD | G22: 116 | I22: ETA | J22: ETD | L22: =COUNTA(B28)+L21 -> 17 | M22: =C28 -> 12205 WILIAM | N22: DNK | O22: 28 | P22: 106 | U22: =B28 -> 2 | X22: =IF(D28=0,"",D28) | Y22: =IF(E28=0,"",E28) | Z22: 0102 | AA22: =VLOOKUP($M:$M,Data!$I:$J,2,FALSE) -> #N/A
B23: 1 | C23: =VLOOKUP("28/105/1",Data!$A$2:$E$1425,3,FALSE) -> 12109 THERRAPHAN | G23: 1 | H23: =VLOOKUP("28/116/1",Data!$A$2:$E$1425,3,FALSE) -> 12204 JOAKIM | L23: =COUNTA(B29)+L22 -> 18 | M23: =C29 -> 0 | N23: DNK | O23: 28 | P23: 106 | U23: =B29 -> 3 | X23: =IF(D29=0,"",D29) | Y23: =IF(E29=0,"",E29) | Z23: 0103 | AA23: =VLOOKUP($M:$M,Data!$I:$J,2,FALSE) -> #N/A
B24: 2 | C24: =VLOOKUP("28/105/2",Data!$A$2:$E$1425,3,FALSE) -> 12110 ALEXANDER | G24: 2 | H24: =VLOOKUP("28/116/2",Data!$A$2:$E$1425,3,FALSE) -> 12207 ELIAS | L24: =COUNTA(B31)+L23 -> 19 | M24: =C31 -> 12210 ALEXANDER | N24: DNK | O24: 28 | P24: 107 | Q24: =_xlfn.IFS(COUNTA(B31:B33)=1,"Single",COUNTA(B31:B33)=2,"Double",COUNTA(B31:B33)=3,"Triple",COUNTA(B31:B33)=0,"Empty") -> Triple | U24: =B31 -> 1 | V24: =COUNT(B31:B33) -> 3 | X24: =IF(D31=0,"",D31) | Y24: =IF(E31=0,"",E31) | Z24: 0104 | AA24: =VLOOKUP($M:$M,Data!$I:$J,2,FALSE) -> #N/A
B25: 3 | C25: =VLOOKUP("28/105/3",Data!$A$2:$E$1425,3,FALSE) -> 0 | H25: =VLOOKUP("28/116/3",Data!$A$2:$E$1425,3,FALSE) -> 0 | L25: =COUNTA(B32)+L24 -> 20 | M25: =C32 -> 12206 ELIAS | N25: DNK | O25: 28 | P25: 107 | U25: =B32 -> 2 | X25: =IF(D32=0,"",D32) | Y25: =IF(E32=0,"",E32) | Z25: 0105 | AA25: =VLOOKUP($M:$M,Data!$I:$J,2,FALSE) -> #N/A
B26: 106 | D26: ETA | E26: ETD | G26: Drying room | L26: =COUNTA(B33)+L25 -> 21 | M26: =C33 -> 0 | N26: DNK | O26: 28 | P26: 107 | U26: =B33 -> 3 | X26: =IF(D33=0,"",D33) | Y26: =IF(E33=0,"",E33) | Z26: 0106 | AA26: =VLOOKUP($M:$M,Data!$I:$J,2,FALSE) -> #N/A
